Collecting unqlite==0.9.2 (from -r D:/Windsor/WindsorThesis/Git repo/Thesis-Project-Python-Dependency-Conflict-Resolution/Dataset/gist/main_gist\requirements.8c9644f9666d60cad37b.txt (line 1))
  Downloading unqlite-0.9.2.tar.gz (575 kB)
     -------------------------------------- 575.2/575.2 kB 1.3 MB/s eta 0:00:00
  Installing build dependencies: started
  Installing build dependencies: finished with status 'done'
  Getting requirements to build wheel: started
  Getting requirements to build wheel: finished with status 'done'
  Installing backend dependencies: started
  Installing backend dependencies: finished with status 'done'
  Preparing metadata (pyproject.toml): started
  Preparing metadata (pyproject.toml): finished with status 'error'
  error: subprocess-exited-with-error
  
  Preparing metadata (pyproject.toml) did not run successfully.
  exit code: 1
  
  [65 lines of output]
  
  Error compiling Cython file:
  ------------------------------------------------------------
  ...
          script = '$ret = db_fetch_all($collection, _filter_fn)'
          with VM(self.unqlite, script) as vm:
              unqlite_create_function(
                  vm.vm,
                  '_filter_fn',
                  filter_callback,
                  ^
  ------------------------------------------------------------
  
  unqlite.pyx:1102:16: Cannot assign type 'unqlite_filter_fn' (alias of 'int (*)(unqlite_context *, int, unqlite_value **) except *') to 'int (*)(unqlite_context *, int, unqlite_value **) noexcept'. Exception values are incompatible. Suggest adding 'noexcept' to the type of 'filter_callback'.
  
  Error compiling Cython file:
  ------------------------------------------------------------
  ...
  
      if unqlite_value_is_json_object(ptr):
          json_object = {}
          unqlite_array_walk(
              ptr,
              unqlite_value_to_dict,
              ^
  ------------------------------------------------------------
  
  unqlite.pyx:1261:12: Cannot assign type 'int (unqlite_value *, unqlite_value *, void *) except? -1' to 'int (*)(unqlite_value *, unqlite_value *, void *) noexcept'. Exception values are incompatible. Suggest adding 'noexcept' to the type of 'unqlite_value_to_dict'.
  
  Error compiling Cython file:
  ------------------------------------------------------------
  ...
          return json_object
      elif unqlite_value_is_json_array(ptr):
          json_array = []
          unqlite_array_walk(
              ptr,
              unqlite_value_to_list,
              ^
  ------------------------------------------------------------
  
  unqlite.pyx:1268:12: Cannot assign type 'int (unqlite_value *, unqlite_value *, void *) except? -1' to 'int (*)(unqlite_value *, unqlite_value *, void *) noexcept'. Exception values are incompatible. Suggest adding 'noexcept' to the type of 'unqlite_value_to_list'.
  Compiling unqlite.pyx because it changed.
  [1/1] Cythonizing unqlite.pyx
  Traceback (most recent call last):
    File "D:\Windsor\WindsorThesis\Git repo\Thesis-Project-Python-Dependency-Conflict-Resolution\pipTest\myenv\Lib\site-packages\pip\_vendor\pyproject_hooks\_in_process\_in_process.py", line 353, in <module>
      main()
    File "D:\Windsor\WindsorThesis\Git repo\Thesis-Project-Python-Dependency-Conflict-Resolution\pipTest\myenv\Lib\site-packages\pip\_vendor\pyproject_hooks\_in_process\_in_process.py", line 335, in main
      json_out['return_val'] = hook(**hook_input['kwargs'])
                               ^^^^^^^^^^^^^^^^^^^^^^^^^^^^
    File "D:\Windsor\WindsorThesis\Git repo\Thesis-Project-Python-Dependency-Conflict-Resolution\pipTest\myenv\Lib\site-packages\pip\_vendor\pyproject_hooks\_in_process\_in_process.py", line 149, in prepare_metadata_for_build_wheel
      return hook(metadata_directory, config_settings)
             ^^^^^^^^^^^^^^^^^^^^^^^^^^^^^^^^^^^^^^^^^
    File "C:\Users\ASUS\AppData\Local\Temp\pip-build-env-vaz9hhbp\overlay\Lib\site-packages\setuptools\build_meta.py", line 368, in prepare_metadata_for_build_wheel
      self.run_setup()
    File "C:\Users\ASUS\AppData\Local\Temp\pip-build-env-vaz9hhbp\overlay\Lib\site-packages\setuptools\build_meta.py", line 497, in run_setup
      super().run_setup(setup_script=setup_script)
    File "C:\Users\ASUS\AppData\Local\Temp\pip-build-env-vaz9hhbp\overlay\Lib\site-packages\setuptools\build_meta.py", line 313, in run_setup
      exec(code, locals())
    File "<string>", line 56, in <module>
    File "C:\Users\ASUS\AppData\Local\Temp\pip-build-env-vaz9hhbp\normal\Lib\site-packages\Cython\Build\Dependencies.py", line 1154, in cythonize
      cythonize_one(*args)
    File "C:\Users\ASUS\AppData\Local\Temp\pip-build-env-vaz9hhbp\normal\Lib\site-packages\Cython\Build\Dependencies.py", line 1321, in cythonize_one
      raise CompileError(None, pyx_file)
  Cython.Compiler.Errors.CompileError: unqlite.pyx
  [end of output]
  
  note: This error originates from a subprocess, and is likely not a problem with pip.
error: metadata-generation-failed

Encountered error while generating package metadata.

See above for output.

note: This is an issue with the package mentioned above, not pip.
hint: See above for details.

[notice] A new release of pip is available: 23.2.1 -> 24.1.2
[notice] To update, run: D:\Windsor\WindsorThesis\Git repo\Thesis-Project-Python-Dependency-Conflict-Resolution\pipTest\myenv\Scripts\python.exe -m pip install --upgrade pip
